Workbook

Sheet Timeline
A1: Phase | B1: Start Date | C1: End Date | D1: Description | E1: Sources | F1: u_min | G1: u_max | H1: v_t | I1: Sources: v_t taken from vaccination sheet
A2: 1 | B2: 43914 | C2: 44033 | D2: Nationwide lockdown | E2: Sharma et al. | F2: 0.65 | G2: 0.85 | H2: =Vaccination!S203 -> 0
A3: 2 | B3: 44034 | C3: 44061 | D3: Gradual reopening after lifting lockdown | E3: Rayamajhee et al. | F3: 0.4 | G3: 0.55 | H3: =Vaccination!S231 -> 0
A4: 3 | B4: 44062 | C4: 44119 | D4: Capital city preventive orders | E4: Kathmandu Post (2020/9/8) | F4: 0.5 | G4: 0.6 | H4: =Vaccination!S289 -> 0
A5: 4 | B5: 44120 | C5: 44135 | D5: Dashain 2020 festival guidance | E5: dpnet.org.np (2020/8/6) | F5: 0.2 | G5: 0.35 | H5: =Vaccination!S305 -> 0
A6: 5 | B6: 44136 | C6: 44155 | D6: Post-festival local NPIs | E6: Kathmandu Post (2020/11/6) | F6: 0.4 | G6: 0.55 | H6: =Vaccination!S325 -> 0
A7: 6 | B7: 44156 | C7: 44222 | D7: Winter NPIs (local level) | E7: Kathmandu Post (2020/12/1) | F7: 0.3 | G7: 0.4 | H7: =Vaccination!S392 -> 0
A8: 7 | B8: 44223 | C8: 44286 | D8: Vaccination campaign begins ( first and second phases) | E8: (who.int/nepal/news (2021/1/27) | F8: 0.35 | G8: 0.45 | H8: =Vaccination!S444 -> 0.0262
A9: 8 | B9: 44287 | C9: 44314 | D9: Rising cases pre-Delta warnings | E9: cdn.who.int/media (Situation Update # 51) | F9: 0.45 | G9: 0.5 | H9: =Vaccination!S484 -> 0.03425
A10: 9 | B10: 44315 | C10: 44439 | D10: Delta-prohibitory lockdown | E10: Adhikari et al. | F10: 0.7 | G10: 0.85 | H10: =Vaccination!S609 -> 0.1604
A11: 10 | B11: 44440 | C11: 44468 | D11: Reopening (moderate NPIs; schools conditional) | E11: Kathmandu Post (2021/9/2) | F11: 0.35 | G11: 0.45 | H11: =Vaccination!S638 -> 0.2202
A12: 11 | B12: 44469 | C12: 44511 | D12: Dashain, Tihar 2021 (festival guidelines) | E12: Kathmandu Post (2021/9/30) | F12: 0.2 | G12: 0.3 | H12: =Vaccination!S677 -> 0.2647
A13: 12 | B13: 44512 | C13: 44567 | D13: Post-festival period (vaccination scale-up) | E13: Kathmandu Post (2021/11/22) | F13: 0.4 | G13: 0.5 | H13: =Vaccination!S735 -> 0.4137
A14: 13 | B14: 44568 | C14: 44598 | D14: Omicron response (vaccination card for services) | E14: nmc.org.np (2022/1/24) | F14: 0.55 | G14: 0.65 | H14: =Vaccination!S762 -> 0.51135
A15: 14 | B15: 44599 | C15: 44624 | D15: Pre-lifting transition | E15: The Himalayan Times (2022/2/7) | F15: 0.35 | G15: 0.45 | H15: =Vaccination!S794 -> 0.6434
A16: 15 | B16: 44625 | C16: 44829 | D16: All restrictions lifted (endemic transition) | E16: The Himalayan Times (2022/3/4) | F16: 0.05 | G16: 0.25 | H16: =Vaccination!S999 -> 0.8137
A17: 16 | B17: 44830 | C17: 44865 | D17: Dashain, Tihar 2022 (normal) | E17: The Himalayan Times (2022/9/30) | F17: 0.05 | G17: 0.2 | H17: =Vaccination!S1027 -> 0.82955
A18: 17 | B18: 44866 | C18: 44895 | D18: Post festival period (normal) | E18: cdn.who.int/media (Situation Update # 133) | F18: 0 | G18: 0.15 | H18: =Vaccination!S1064 -> 0.83895
A19: 18 | B19: 44896 | C19: 44926 | D19: Post-pandemic normalization | E19: cdn.who.int/media (Situation Update # 138) | F19: 0.05 | G19: 0.2 | H19: =Vaccination!S1085 -> 0.84495

Sheet Vaccination
A1: Estimation of overall vaccination coverage (v_t) combining single and full dose coverage from OWID data
A2: v_t = MIN(1, (0.5*MAX(v_1-v_2,0) + 1*v_2)/100 ); v_1=people vaccinated % (one or two dose), v_2=people fully vaccinated %
A3: OWID DATA (filtered columns: Date, Country (Nepal), Vaccination Details | Q3: Computed by User (Shiva Hari Subedi)
A4: Date | B4: Country | C4: total_vaccinations | D4: people_vaccinated | E4: people_fully_vaccinated | F4: total_boosters | G4: new_vaccinations | H4: new_vaccinations_smoothed | I4: total_vaccinations_per_hundred | J4: people_vaccinated_per_hundred | K4: people_fully_vaccinated_per_hundred | L4: total_boosters_per_hundred | M4: new_vaccinations_smoothed_per_million | N4: new_people_vaccinated_smoothed | O4: new_people_vaccinated_smoothed_per_hundred | P4: stringency_index | R4: v_1-v_2 Single dose only (J-K) | S4: v_t
A5: 43835 | B5: Nepal | P5: 0 | R5: =J5-K5 -> 0 | S5: =MIN(1, (0.5*MAX(R5,0) + 1*K5)/100 ) -> 0
A6: 43836 | B6: Nepal | P6: 0 | R6: =J6-K6 -> 0 | S6: =MIN(1, (0.5*MAX(R6,0) + 1*K6)/100 ) -> 0
A7: 43837 | B7: Nepal | P7: 0 | R7: =J7-K7 -> 0 | S7: =MIN(1, (0.5*MAX(R7,0) + 1*K7)/100 ) -> 0
A8: 43838 | B8: Nepal | P8: 0 | R8: =J8-K8 -> 0 | S8: =MIN(1, (0.5*MAX(R8,0) + 1*K8)/100 ) -> 0
A9: 43839 | B9: Nepal | P9: 0 | R9: =J9-K9 -> 0 | S9: =MIN(1, (0.5*MAX(R9,0) + 1*K9)/100 ) -> 0
A10: 43840 | B10: Nepal | P10: 0 | R10: =J10-K10 -> 0 | S10: =MIN(1, (0.5*MAX(R10,0) + 1*K10)/100 ) -> 0
A11: 43841 | B11: Nepal | P11: 0 | R11: =J11-K11 -> 0 | S11: =MIN(1, (0.5*MAX(R11,0) + 1*K11)/100 ) -> 0
A12: 43842 | B12: Nepal | P12: 0 | R12: =J12-K12 -> 0 | S12: =MIN(1, (0.5*MAX(R12,0) + 1*K12)/100 ) -> 0
A13: 43843 | B13: Nepal | P13: 0 | R13: =J13-K13 -> 0 | S13: =MIN(1, (0.5*MAX(R13,0) + 1*K13)/100 ) -> 0
A14: 43844 | B14: Nepal | P14: 0 | R14: =J14-K14 -> 0 | S14: =MIN(1, (0.5*MAX(R14,0) + 1*K14)/100 ) -> 0
A15: 43845 | B15: Nepal | P15: 0 | R15: =J15-K15 -> 0 | S15: =MIN(1, (0.5*MAX(R15,0) + 1*K15)/100 ) -> 0
A16: 43846 | B16: Nepal | P16: 5.56 | R16: =J16-K16 -> 0 | S16: =MIN(1, (0.5*MAX(R16,0) + 1*K16)/100 ) -> 0
... A391: 44221 | B391: Nepal | P391: 57.41 | R391: =J391-K391 -> 0 | S391: =MIN(1, (0.5*MAX(R391,0) + 1*K391)/100 ) -> 0
A392: 44222 | B392: Nepal | C392: 0 | I392: 0 | P392: 57.41 | R392: =J392-K392 -> 0 | S392: =MIN(1, (0.5*MAX(R392,0) + 1*K392)/100 ) -> 0
A393: 44223 | B393: Nepal | H393: 18862 | M393: 617 | P393: 57.41 | R393: =J393-K393 -> 0 | S393: =MIN(1, (0.5*MAX(R393,0) + 1*K393)/100 ) -> 0
A394: 44224 | B394: Nepal | H394: 18862 | M394: 617 | P394: 57.41 | R394: =J394-K394 -> 0 | S394: =MIN(1, (0.5*MAX(R394,0) + 1*K394)/100 ) -> 0
A395: 44225 | B395: Nepal | H395: 18862 | M395: 617 | P395: 57.41 | R395: =J395-K395 -> 0 | S395: =MIN(1, (0.5*MAX(R395,0) + 1*K395)/100 ) -> 0
A396: 44226 | B396: Nepal | H396: 18862 | M396: 617 | P396: 57.41 | R396: =J396-K396 -> 0 | S396: =MIN(1, (0.5*MAX(R396,0) + 1*K396)/100 ) -> 0
A397: 44227 | B397: Nepal | H397: 18862 | M397: 617 | P397: 57.41 | R397: =J397-K397 -> 0 | S397: =MIN(1, (0.5*MAX(R397,0) + 1*K397)/100 ) -> 0
A398: 44228 | B398: Nepal | C398: 113175 | D398: 113175 | H398: 18862 | I398: 0.37 | J398: 0.37 | M398: 617 | P398: 57.41 | R398: =J398-K398 -> 0.37 | S398: =MIN(1, (0.5*MAX(R398,0) + 1*K398)/100 ) -> 0.00185
A399: 44229 | B399: Nepal | H399: 18326 | M399: 600 | N399: 15104 | O399: 0.049 | P399: 57.41 | R399: =J399-K399 -> 0 | S399: =MIN(1, (0.5*MAX(R399,0) + 1*K399)/100 ) -> 0
A400: 44230 | B400: Nepal | H400: 17789 | M400: 582 | N400: 15104 | O400: 0.049 | P400: 57.41 | R400: =J400-K400 -> 0 | S400: =MIN(1, (0.5*MAX(R400,0) + 1*K400)/100 ) -> 0
A401: 44231 | B401: Nepal | C401: 158487 | D401: 158487 | H401: 17252 | I401: 0.52 | J401: 0.52 | M401: 565 | N401: 15104 | O401: 0.049 | P401: 57.41 | R401: =J401-K401 -> 0.52 | S401: =MIN(1, (0.5*MAX(R401,0) + 1*K401)/100 ) -> 0.0026
A402: 44232 | B402: Nepal | H402: 16734 | M402: 548 | N402: 15137 | O402: 0.05 | P402: 57.41 | R402: =J402-K402 -> 0 | S402: =MIN(1, (0.5*MAX(R402,0) + 1*K402)/100 ) -> 0
A403: 44233 | B403: Nepal | H403: 16216 | M403: 531 | N403: 15157 | O403: 0.05 | P403: 57.41 | R403: =J403-K403 -> 0 | S403: =MIN(1, (0.5*MAX(R403,0) + 1*K403)/100 ) -> 0
A404: 44234 | B404: Nepal | H404: 15698 | M404: 514 | N404: 15170 | O404: 0.05 | P404: 57.41 | R404: =J404-K404 -> 0 | S404: =MIN(1, (0.5*MAX(R404,0) + 1*K404)/100 ) -> 0
A405: 44235 | B405: Nepal | H405: 15179 | M405: 497 | N405: 15179 | O405: 0.05 | P405: 57.41 | R405: =J405-K405 -> 0 | S405: =MIN(1, (0.5*MAX(R405,0) + 1*K405)/100 ) -> 0
A406: 44236 | B406: Nepal | H406: 15198 | M406: 498 | N406: 15198 | O406: 0.05 | P406: 57.41 | R406: =J406-K406 -> 0 | S406: =MIN(1, (0.5*MAX(R406,0) + 1*K406)/100 ) -> 0
A407: 44237 | B407: Nepal | H407: 15217 | M407: 498 | N407: 15217 | O407: 0.05 | P407: 57.41 | R407: =J407-K407 -> 0 | S407: =MIN(1, (0.5*MAX(R407,0) + 1*K407)/100 ) -> 0
A408: 44238 | B408: Nepal | H408: 15236 | M408: 499 | N408: 15236 | O408: 0.05 | P408: 52.78 | R408: =J408-K408 -> 0 | S408: =MIN(1, (0.5*MAX(R408,0) + 1*K408)/100 ) -> 0
A409: 44239 | B409: Nepal | H409: 15236 | M409: 499 | N409: 15236 | O409: 0.05 | P409: 52.78 | R409: =J409-K409 -> 0 | S409: =MIN(1, (0.5*MAX(R409,0) + 1*K409)/100 ) -> 0
A410: 44240 | B410: Nepal | H410: 15236 | M410: 499 | N410: 15236 | O410: 0.05 | P410: 52.78 | R410: =J410-K410 -> 0 | S410: =MIN(1, (0.5*MAX(R410,0) + 1*K410)/100 ) -> 0
A411: 44241 | B411: Nepal | H411: 15236 | M411: 499 | N411: 15236 | O411: 0.05 | P411: 52.78 | R411: =J411-K411 -> 0 | S411: =MIN(1, (0.5*MAX(R411,0) + 1*K411)/100 ) -> 0
A412: 44242 | B412: Nepal | H412: 15236 | M412: 499 | N412: 15236 | O412: 0.05 | P412: 52.78 | R412: =J412-K412 -> 0 | S412: =MIN(1, (0.5*MAX(R412,0) + 1*K412)/100 ) -> 0
A413: 44243 | B413: Nepal | H413: 15236 | M413: 499 | N413: 15236 | O413: 0.05 | P413: 52.78 | R413: =J413-K413 -> 0 | S413: =MIN(1, (0.5*MAX(R413,0) + 1*K413)/100 ) -> 0
... A416: 44246 | B416: Nepal | H416: 15236 | M416: 499 | N416: 15236 | O416: 0.05 | P416: 52.78 | R416: =J416-K416 -> 0 | S416: =MIN(1, (0.5*MAX(R416,0) + 1*K416)/100 ) -> 0
...
